# Excecoes no Python

# =================================================================================================
# Mesmo se uma declaração ou expressão estiver sintaticamente correta,
# poderá causar um erro quando for feita uma tentativa de executá-la. 
# Os erros detectados durante a execução são chamados de exceções 
# e não são incondicionalmente fatais: você aprenderá em breve como lidar com eles em programas Python. 

# No Python, as exceções podem ser tratadas usando uma instrução try.
# Uma operação crítica que pode gerar uma exceção é colocada dentro da cláusula try e o 
# código que manipula a exceção é gravado na cláusula exceto.
# Cabe a nós quais operações realizamos depois de capturarmos a exceção. 
# Aqui está um exemplo simples:
import sys
randomList = ['a', 0, ...]
for entry in randomList:
  try:
    r = 1/int(entry)
  except:
    print("Erro: ",sys.exc_info()[0])

# Erro:  <class 'ValueError'>
# Erro:  <class 'ZeroDivisionError'>
# Erro:  <class 'TypeError'>

# =================================================================================================
# Uma cláusula try pode ter qualquer número de exceção, para manipulá-las de maneira diferente, 
# mas apenas uma será executada caso ocorra uma exceção.
# Exemplo:
for entry in randomList:
  try:
    n = 1/int(entry)
  # as -> para apelidar o erro
  except (ValueError, TypeError) as erro: 
    print(erro) 
    # invalid literal for int() with base 10: 'a'
    # int() argument must be a string, a bytes-like object or a number, not 'ellipsis'
  except ZeroDivisionError as erro:
    print(erro) # division by zero

# =================================================================================================
# A instrução try no Python pode ter uma cláusula finalmente opcional. 
# Esta cláusula é executada independentemente do que for e geralmente é usada para liberar recursos externos.
f: "arquivo" = ...
try:
    f = open("test.txt",encoding = 'utf-8')
    # perform file operations
except FileNotFoundError as erro:
  print(erro) # [Errno 2] No such file or directory: 'test.txt'
finally:
  try:
    f.close()
  except:
    print("Arquivo nao pode ser fechado porque nao foi criado.")

# =================================================================================================
# raise classe_de_erro("mensagem")
# Na programação Python, as exceções são geradas quando erros correspondentes ocorrem no tempo de execução, 
# mas podemos chama-las à força usando a palavra-chave raise.
# Exemplo:

try:
  raise Exception
except:
  print("Um erro ocorreu com sucesso!")

# =================================================================================================
# assert (condition),("mensagem")
# O Python possui uma declaração de declaração interna para usar a condição de declaração no programa. 
# A declaração assert tem uma condição ou expressão que deveria ser sempre verdadeira. 
# Se a condição for falsa, a declaração interrompe o programa e fornece um AssertionError.
# Exemplo:

x = 1
try: 
  assert (x == 0),("Um erro ocorreu.")
except:
  print("Um AssertionError ocorreu.")

# =================================================================================================
# Arvore de erros abrangidos pelo Python:
# BaseException
#  +-- SystemExit
#  +-- KeyboardInterrupt
#  +-- GeneratorExit
#  +-- Exception
#       +-- StopIteration
#       +-- StopAsyncIteration
#       +-- ArithmeticError
#       |    +-- FloatingPointError
#       |    +-- OverflowError
#       |    +-- ZeroDivisionError
#       +-- AssertionError
#       +-- AttributeError
#       +-- BufferError
#       +-- EOFError
#       +-- ImportError
#       |    +-- ModuleNotFoundError
#       +-- LookupError
#       |    +-- IndexError
#       |    +-- KeyError
#       +-- MemoryError
#       +-- NameError
#       |    +-- UnboundLocalError
#       +-- OSError
#       |    +-- BlockingIOError
#       |    +-- ChildProcessError
#       |    +-- ConnectionError
#       |    |    +-- BrokenPipeError
#       |    |    +-- ConnectionAbortedError
#       |    |    +-- ConnectionRefusedError
#       |    |    +-- ConnectionResetError
#       |    +-- FileExistsError
#       |    +-- FileNotFoundError
#       |    +-- InterruptedError
#       |    +-- IsADirectoryError
#       |    +-- NotADirectoryError
#       |    +-- PermissionError
#       |    +-- ProcessLookupError
#       |    +-- TimeoutError
#       +-- ReferenceError
#       +-- RuntimeError
#       |    +-- NotImplementedError
#       |    +-- RecursionError
#       +-- SyntaxError
#       |    +-- IndentationError
#       |         +-- TabError
#       +-- SystemError
#       +-- TypeError
#       +-- ValueError
#       |    +-- UnicodeError
#       |         +-- UnicodeDecodeError
#       |         +-- UnicodeEncodeError
#       |         +-- UnicodeTranslateError
#       +-- Warning
#            +-- DeprecationWarning
#            +-- PendingDeprecationWarning
#            +-- RuntimeWarning
#            +-- SyntaxWarning
#            +-- UserWarning
#            +-- FutureWarning
#            +-- ImportWarning
#            +-- UnicodeWarning
#            +-- BytesWarning
#            +-- ResourceWarning


# =================================================================================================
# Criando uma classe de erro:
class ErroDeDivisaoPorZero (ZeroDivisionError):
  pass

try:
  raise ErroDeDivisaoPorZero
except ErroDeDivisaoPorZero:
  print("ErroDeDivisaoPorZero ocorreu.")

try:
  raise ErroDeDivisaoPorZero("argumento")
except ErroDeDivisaoPorZero as erro_zero:
  print(erro_zero.args)
  print(erro_zero.with_traceback(print(44)))









